<?xml version="1.0" encoding="UTF-8"?>
<testng-results retried="3" ignored="0" total="4" passed="0" failed="1" skipped="0">
  <reporter-output>
    <line>
      <![CDATA[Test suite is started]]>
    </line>
    <line>
      <![CDATA[Test case is started]]>
    </line>
    <line>
      <![CDATA[Test case is started]]>
    </line>
    <line>
      <![CDATA[Test case is started]]>
    </line>
    <line>
      <![CDATA[Test case is started]]>
    </line>
    <line>
      <![CDATA[Test case is failed]]>
    </line>
  </reporter-output>
  <suite started-at="2024-05-15T21:12:18 IST" name="Default suite" finished-at="2024-05-15T21:13:25 IST" duration-ms="66888">
    <groups>
    </groups>
    <test started-at="2024-05-15T21:12:18 IST" name="Default test" finished-at="2024-05-15T21:13:25 IST" duration-ms="66888">
      <class name="Amazon.Project_On_Amazon.Test_1">
        <test-method is-config="true" signature="launch_and_signIn()[pri:0, instance:Amazon.Project_On_Amazon.Test_1@3d8bbcdc]" started-at="2024-05-15T21:12:18 IST" name="launch_and_signIn" finished-at="2024-05-15T21:13:01 IST" duration-ms="43187" status="PASS">
          <reporter-output>
          </reporter-output>
        </test-method> <!-- launch_and_signIn -->
        <test-method retried="true" signature="test_1_One()[pri:-9, instance:Amazon.Project_On_Amazon.Test_1@3d8bbcdc]" started-at="2024-05-15T21:13:01 IST" name="test_1_One" finished-at="2024-05-15T21:13:02 IST" duration-ms="671" status="SKIP">
          <exception class="java.lang.AssertionError">
            <message>
              <![CDATA[did not expect [false] but found [false]]]>
            </message>
            <full-stacktrace>
              <![CDATA[java.lang.AssertionError: did not expect [false] but found [false]
at org.testng.Assert.fail(Assert.java:99)
at org.testng.Assert.failEquals(Assert.java:1041)
at org.testng.Assert.assertNotEqualsImpl(Assert.java:147)
at org.testng.Assert.assertNotEquals(Assert.java:1531)
at org.testng.Assert.assertNotEquals(Assert.java:1535)
at Amazon.Project_On_Amazon.Test_1.test_1_One(Test_1.java:20)
at java.base/jdk.internal.reflect.NativeMethodAccessorImpl.invoke0(Native Method)
at java.base/jdk.internal.reflect.NativeMethodAccessorImpl.invoke(NativeMethodAccessorImpl.java:77)
at java.base/jdk.internal.reflect.DelegatingMethodAccessorImpl.invoke(DelegatingMethodAccessorImpl.java:43)
at java.base/java.lang.reflect.Method.invoke(Method.java:568)
at org.testng.internal.MethodInvocationHelper.invokeMethod(MethodInvocationHelper.java:133)
at org.testng.internal.TestInvoker.invokeMethod(TestInvoker.java:598)
at org.testng.internal.TestInvoker.invokeTestMethod(TestInvoker.java:173)
at org.testng.internal.MethodRunner.runInSequence(MethodRunner.java:46)
at org.testng.internal.TestInvoker$MethodInvocationAgent.invoke(TestInvoker.java:824)
at org.testng.internal.TestInvoker.invokeTestMethods(TestInvoker.java:146)
at org.testng.internal.TestMethodWorker.invokeTestMethods(TestMethodWorker.java:146)
at org.testng.internal.TestMethodWorker.run(TestMethodWorker.java:128)
at java.base/java.util.ArrayList.forEach(ArrayList.java:1511)
at org.testng.TestRunner.privateRun(TestRunner.java:794)
at org.testng.TestRunner.run(TestRunner.java:596)
at org.testng.SuiteRunner.runTest(SuiteRunner.java:377)
at org.testng.SuiteRunner.runSequentially(SuiteRunner.java:371)
at org.testng.SuiteRunner.privateRun(SuiteRunner.java:332)
at org.testng.SuiteRunner.run(SuiteRunner.java:276)
at org.testng.SuiteRunnerWorker.runSuite(SuiteRunnerWorker.java:53)
at org.testng.SuiteRunnerWorker.run(SuiteRunnerWorker.java:96)
at org.testng.TestNG.runSuitesSequentially(TestNG.java:1212)
at org.testng.TestNG.runSuitesLocally(TestNG.java:1134)
at org.testng.TestNG.runSuites(TestNG.java:1063)
at org.testng.TestNG.run(TestNG.java:1031)
at org.testng.remote.AbstractRemoteTestNG.run(AbstractRemoteTestNG.java:115)
at org.testng.remote.RemoteTestNG.initAndRun(RemoteTestNG.java:251)
at org.testng.remote.RemoteTestNG.main(RemoteTestNG.java:77)
]]>
            </full-stacktrace>
          </exception> <!-- java.lang.AssertionError -->
          <reporter-output>
            <line>
              <![CDATA[Test case is started]]>
            </line>
          </reporter-output>
        </test-method> <!-- test_1_One -->
        <test-method is-config="true" signature="launch_and_signIn()[pri:0, instance:Amazon.Project_On_Amazon.Test_1@3d8bbcdc]" started-at="2024-05-15T21:13:03 IST" name="launch_and_signIn" finished-at="2024-05-15T21:13:11 IST" duration-ms="8434" status="PASS">
          <reporter-output>
          </reporter-output>
        </test-method> <!-- launch_and_signIn -->
        <test-method retried="true" signature="test_1_One()[pri:-9, instance:Amazon.Project_On_Amazon.Test_1@3d8bbcdc]" started-at="2024-05-15T21:13:11 IST" name="test_1_One" finished-at="2024-05-15T21:13:11 IST" duration-ms="309" status="SKIP">
          <exception class="java.lang.AssertionError">
            <message>
              <![CDATA[did not expect [false] but found [false]]]>
            </message>
            <full-stacktrace>
              <![CDATA[java.lang.AssertionError: did not expect [false] but found [false]
at org.testng.Assert.fail(Assert.java:99)
at org.testng.Assert.failEquals(Assert.java:1041)
at org.testng.Assert.assertNotEqualsImpl(Assert.java:147)
at org.testng.Assert.assertNotEquals(Assert.java:1531)
at org.testng.Assert.assertNotEquals(Assert.java:1535)
at Amazon.Project_On_Amazon.Test_1.test_1_One(Test_1.java:20)
at java.base/jdk.internal.reflect.NativeMethodAccessorImpl.invoke0(Native Method)
at java.base/jdk.internal.reflect.NativeMethodAccessorImpl.invoke(NativeMethodAccessorImpl.java:77)
at java.base/jdk.internal.reflect.DelegatingMethodAccessorImpl.invoke(DelegatingMethodAccessorImpl.java:43)
at java.base/java.lang.reflect.Method.invoke(Method.java:568)
at org.testng.internal.MethodInvocationHelper.invokeMethod(MethodInvocationHelper.java:133)
at org.testng.internal.TestInvoker.invokeMethod(TestInvoker.java:598)
at org.testng.internal.TestInvoker.retryFailed(TestInvoker.java:213)
at org.testng.internal.MethodRunner.runInSequence(MethodRunner.java:58)
at org.testng.internal.TestInvoker$MethodInvocationAgent.invoke(TestInvoker.java:824)
at org.testng.internal.TestInvoker.invokeTestMethods(TestInvoker.java:146)
at org.testng.internal.TestMethodWorker.invokeTestMethods(TestMethodWorker.java:146)
at org.testng.internal.TestMethodWorker.run(TestMethodWorker.java:128)
at java.base/java.util.ArrayList.forEach(ArrayList.java:1511)
at org.testng.TestRunner.privateRun(TestRunner.java:794)
at org.testng.TestRunner.run(TestRunner.java:596)
at org.testng.SuiteRunner.runTest(SuiteRunner.java:377)
at org.testng.SuiteRunner.runSequentially(SuiteRunner.java:371)
at org.testng.SuiteRunner.privateRun(SuiteRunner.java:332)
at org.testng.SuiteRunner.run(SuiteRunner.java:276)
at org.testng.SuiteRunnerWorker.runSuite(SuiteRunnerWorker.java:53)
at org.testng.SuiteRunnerWorker.run(SuiteRunnerWorker.java:96)
at org.testng.TestNG.runSuitesSequentially(TestNG.java:1212)
at org.testng.TestNG.runSuitesLocally(TestNG.java:1134)
at org.testng.TestNG.runSuites(TestNG.java:1063)
at org.testng.TestNG.run(TestNG.java:1031)
at org.testng.remote.AbstractRemoteTestNG.run(AbstractRemoteTestNG.java:115)
at org.testng.remote.RemoteTestNG.initAndRun(RemoteTestNG.java:251)
at org.testng.remote.RemoteTestNG.main(RemoteTestNG.java:77)
]]>
            </full-stacktrace>
          </exception> <!-- java.lang.AssertionError -->
          <reporter-output>
            <line>
              <![CDATA[Test case is started]]>
            </line>
          </reporter-output>
        </test-method> <!-- test_1_One -->
        <test-method is-config="true" signature="launch_and_signIn()[pri:0, instance:Amazon.Project_On_Amazon.Test_1@3d8bbcdc]" started-at="2024-05-15T21:13:12 IST" name="launch_and_signIn" finished-at="2024-05-15T21:13:14 IST" duration-ms="2240" status="PASS">
          <reporter-output>
          </reporter-output>
        </test-method> <!-- launch_and_signIn -->
        <test-method retried="true" signature="test_1_One()[pri:-9, instance:Amazon.Project_On_Amazon.Test_1@3d8bbcdc]" started-at="2024-05-15T21:13:14 IST" name="test_1_One" finished-at="2024-05-15T21:13:14 IST" duration-ms="372" status="SKIP">
          <exception class="java.lang.AssertionError">
            <message>
              <![CDATA[did not expect [false] but found [false]]]>
            </message>
            <full-stacktrace>
              <![CDATA[java.lang.AssertionError: did not expect [false] but found [false]
at org.testng.Assert.fail(Assert.java:99)
at org.testng.Assert.failEquals(Assert.java:1041)
at org.testng.Assert.assertNotEqualsImpl(Assert.java:147)
at org.testng.Assert.assertNotEquals(Assert.java:1531)
at org.testng.Assert.assertNotEquals(Assert.java:1535)
at Amazon.Project_On_Amazon.Test_1.test_1_One(Test_1.java:20)
at java.base/jdk.internal.reflect.NativeMethodAccessorImpl.invoke0(Native Method)
at java.base/jdk.internal.reflect.NativeMethodAccessorImpl.invoke(NativeMethodAccessorImpl.java:77)
at java.base/jdk.internal.reflect.DelegatingMethodAccessorImpl.invoke(DelegatingMethodAccessorImpl.java:43)
at java.base/java.lang.reflect.Method.invoke(Method.java:568)
at org.testng.internal.MethodInvocationHelper.invokeMethod(MethodInvocationHelper.java:133)
at org.testng.internal.TestInvoker.invokeMethod(TestInvoker.java:598)
at org.testng.internal.TestInvoker.retryFailed(TestInvoker.java:213)
at org.testng.internal.MethodRunner.runInSequence(MethodRunner.java:58)
at org.testng.internal.TestInvoker$MethodInvocationAgent.invoke(TestInvoker.java:824)
at org.testng.internal.TestInvoker.invokeTestMethods(TestInvoker.java:146)
at org.testng.internal.TestMethodWorker.invokeTestMethods(TestMethodWorker.java:146)
at org.testng.internal.TestMethodWorker.run(TestMethodWorker.java:128)
at java.base/java.util.ArrayList.forEach(ArrayList.java:1511)
at org.testng.TestRunner.privateRun(TestRunner.java:794)
at org.testng.TestRunner.run(TestRunner.java:596)
at org.testng.SuiteRunner.runTest(SuiteRunner.java:377)
at org.testng.SuiteRunner.runSequentially(SuiteRunner.java:371)
at org.testng.SuiteRunner.privateRun(SuiteRunner.java:332)
at org.testng.SuiteRunner.run(SuiteRunner.java:276)
at org.testng.SuiteRunnerWorker.runSuite(SuiteRunnerWorker.java:53)
at org.testng.SuiteRunnerWorker.run(SuiteRunnerWorker.java:96)
at org.testng.TestNG.runSuitesSequentially(TestNG.java:1212)
at org.testng.TestNG.runSuitesLocally(TestNG.java:1134)
at org.testng.TestNG.runSuites(TestNG.java:1063)
at org.testng.TestNG.run(TestNG.java:1031)
at org.testng.remote.AbstractRemoteTestNG.run(AbstractRemoteTestNG.java:115)
at org.testng.remote.RemoteTestNG.initAndRun(RemoteTestNG.java:251)
at org.testng.remote.RemoteTestNG.main(RemoteTestNG.java:77)
]]>
            </full-stacktrace>
          </exception> <!-- java.lang.AssertionError -->
          <reporter-output>
            <line>
              <![CDATA[Test case is started]]>
            </line>
          </reporter-output>
        </test-method> <!-- test_1_One -->
        <test-method is-config="true" signature="launch_and_signIn()[pri:0, instance:Amazon.Project_On_Amazon.Test_1@3d8bbcdc]" started-at="2024-05-15T21:13:15 IST" name="launch_and_signIn" finished-at="2024-05-15T21:13:24 IST" duration-ms="8677" status="PASS">
          <reporter-output>
          </reporter-output>
        </test-method> <!-- launch_and_signIn -->
        <test-method signature="test_1_One()[pri:-9, instance:Amazon.Project_On_Amazon.Test_1@3d8bbcdc]" started-at="2024-05-15T21:13:24 IST" name="test_1_One" finished-at="2024-05-15T21:13:24 IST" duration-ms="551" status="FAIL">
          <exception class="java.lang.AssertionError">
            <message>
              <![CDATA[did not expect [false] but found [false]]]>
            </message>
            <full-stacktrace>
              <![CDATA[java.lang.AssertionError: did not expect [false] but found [false]
at org.testng.Assert.fail(Assert.java:99)
at org.testng.Assert.failEquals(Assert.java:1041)
at org.testng.Assert.assertNotEqualsImpl(Assert.java:147)
at org.testng.Assert.assertNotEquals(Assert.java:1531)
at org.testng.Assert.assertNotEquals(Assert.java:1535)
at Amazon.Project_On_Amazon.Test_1.test_1_One(Test_1.java:20)
at java.base/jdk.internal.reflect.NativeMethodAccessorImpl.invoke0(Native Method)
at java.base/jdk.internal.reflect.NativeMethodAccessorImpl.invoke(NativeMethodAccessorImpl.java:77)
at java.base/jdk.internal.reflect.DelegatingMethodAccessorImpl.invoke(DelegatingMethodAccessorImpl.java:43)
at java.base/java.lang.reflect.Method.invoke(Method.java:568)
at org.testng.internal.MethodInvocationHelper.invokeMethod(MethodInvocationHelper.java:133)
at org.testng.internal.TestInvoker.invokeMethod(TestInvoker.java:598)
at org.testng.internal.TestInvoker.retryFailed(TestInvoker.java:213)
at org.testng.internal.MethodRunner.runInSequence(MethodRunner.java:58)
at org.testng.internal.TestInvoker$MethodInvocationAgent.invoke(TestInvoker.java:824)
at org.testng.internal.TestInvoker.invokeTestMethods(TestInvoker.java:146)
at org.testng.internal.TestMethodWorker.invokeTestMethods(TestMethodWorker.java:146)
at org.testng.internal.TestMethodWorker.run(TestMethodWorker.java:128)
at java.base/java.util.ArrayList.forEach(ArrayList.java:1511)
at org.testng.TestRunner.privateRun(TestRunner.java:794)
at org.testng.TestRunner.run(TestRunner.java:596)
at org.testng.SuiteRunner.runTest(SuiteRunner.java:377)
at org.testng.SuiteRunner.runSequentially(SuiteRunner.java:371)
at org.testng.SuiteRunner.privateRun(SuiteRunner.java:332)
at org.testng.SuiteRunner.run(SuiteRunner.java:276)
at org.testng.SuiteRunnerWorker.runSuite(SuiteRunnerWorker.java:53)
at org.testng.SuiteRunnerWorker.run(SuiteRunnerWorker.java:96)
at org.testng.TestNG.runSuitesSequentially(TestNG.java:1212)
at org.testng.TestNG.runSuitesLocally(TestNG.java:1134)
at org.testng.TestNG.runSuites(TestNG.java:1063)
at org.testng.TestNG.run(TestNG.java:1031)
at org.testng.remote.AbstractRemoteTestNG.run(AbstractRemoteTestNG.java:115)
at org.testng.remote.RemoteTestNG.initAndRun(RemoteTestNG.java:251)
at org.testng.remote.RemoteTestNG.main(RemoteTestNG.java:77)
]]>
            </full-stacktrace>
          </exception> <!-- java.lang.AssertionError -->
          <reporter-output>
            <line>
              <![CDATA[Test case is started]]>
            </line>
            <line>
              <![CDATA[Test case is failed]]>
            </line>
          </reporter-output>
        </test-method> <!-- test_1_One -->
      </class> <!-- Amazon.Project_On_Amazon.Test_1 -->
    </test> <!-- Default test -->
  </suite> <!-- Default suite -->
</testng-results>
