<?xml version="1.0" encoding="UTF-8"?>
<!-- Generated by org.testng.reporters.JUnitReportReporter -->
<testsuite hostname="LAPTOP-KHONK8Q1" failures="1" tests="4" name="Amazon.Project_On_Amazon.Test_1" time="64.441" errors="0" timestamp="2024-05-15T21:13:25 IST" skipped="3">
  <testcase classname="Amazon.Project_On_Amazon.Test_1" name="test_1_One" time="9.105">
    <skipped/>
  </testcase> <!-- test_1_One -->
  <system-out>
    <![CDATA[Test case is started]]>
  </system-out>
  <testcase classname="Amazon.Project_On_Amazon.Test_1" name="test_1_One" time="9.049">
    <skipped/>
  </testcase> <!-- test_1_One -->
  <system-out>
    <![CDATA[Test case is started]]>
  </system-out>
  <testcase classname="Amazon.Project_On_Amazon.Test_1" name="test_1_One" time="2.549">
    <skipped/>
  </testcase> <!-- test_1_One -->
  <system-out>
    <![CDATA[Test case is started]]>
  </system-out>
  <testcase classname="Amazon.Project_On_Amazon.Test_1" name="test_1_One" time="43.738">
    <failure message="did not expect [false] but found [false]" type="java.lang.AssertionError">
      <![CDATA[java.lang.AssertionError: did not expect [false] but found [false]
at org.testng.Assert.fail(Assert.java:99)
at org.testng.Assert.failEquals(Assert.java:1041)
at org.testng.Assert.assertNotEqualsImpl(Assert.java:147)
at org.testng.Assert.assertNotEquals(Assert.java:1531)
at org.testng.Assert.assertNotEquals(Assert.java:1535)
at Amazon.Project_On_Amazon.Test_1.test_1_One(Test_1.java:20)
at java.base/jdk.internal.reflect.NativeMethodAccessorImpl.invoke0(Native Method)
at java.base/jdk.internal.reflect.NativeMethodAccessorImpl.invoke(NativeMethodAccessorImpl.java:77)
at java.base/jdk.internal.reflect.DelegatingMethodAccessorImpl.invoke(DelegatingMethodAccessorImpl.java:43)
at java.base/java.lang.reflect.Method.invoke(Method.java:568)
at org.testng.internal.MethodInvocationHelper.invokeMethod(MethodInvocationHelper.java:133)
at org.testng.internal.TestInvoker.invokeMethod(TestInvoker.java:598)
at org.testng.internal.TestInvoker.retryFailed(TestInvoker.java:213)
at org.testng.internal.MethodRunner.runInSequence(MethodRunner.java:58)
at org.testng.internal.TestInvoker$MethodInvocationAgent.invoke(TestInvoker.java:824)
at org.testng.internal.TestInvoker.invokeTestMethods(TestInvoker.java:146)
at org.testng.internal.TestMethodWorker.invokeTestMethods(TestMethodWorker.java:146)
at org.testng.internal.TestMethodWorker.run(TestMethodWorker.java:128)
at java.base/java.util.ArrayList.forEach(ArrayList.java:1511)
at org.testng.TestRunner.privateRun(TestRunner.java:794)
at org.testng.TestRunner.run(TestRunner.java:596)
at org.testng.SuiteRunner.runTest(SuiteRunner.java:377)
at org.testng.SuiteRunner.runSequentially(SuiteRunner.java:371)
at org.testng.SuiteRunner.privateRun(SuiteRunner.java:332)
at org.testng.SuiteRunner.run(SuiteRunner.java:276)
at org.testng.SuiteRunnerWorker.runSuite(SuiteRunnerWorker.java:53)
at org.testng.SuiteRunnerWorker.run(SuiteRunnerWorker.java:96)
at org.testng.TestNG.runSuitesSequentially(TestNG.java:1212)
at org.testng.TestNG.runSuitesLocally(TestNG.java:1134)
at org.testng.TestNG.runSuites(TestNG.java:1063)
at org.testng.TestNG.run(TestNG.java:1031)
at org.testng.remote.AbstractRemoteTestNG.run(AbstractRemoteTestNG.java:115)
at org.testng.remote.RemoteTestNG.initAndRun(RemoteTestNG.java:251)
at org.testng.remote.RemoteTestNG.main(RemoteTestNG.java:77)
]]>
    </failure>
  </testcase> <!-- test_1_One -->
  <system-out>
    <![CDATA[Test case is started
Test case is failed]]>
  </system-out>
</testsuite> <!-- Amazon.Project_On_Amazon.Test_1 -->
